Workbook

Sheet INSTRUCCIONES
B1: IAM Intelligence™ — Assessment Inicial de Productividad · Comfacesar 2026
B4: CÓMO USAR ESTE ARCHIVO
B5: 1. Abre la hoja del grupo con el que vas a sesionar (ej: COMUNICACIONES).
B6: 2. Los nombres de los participantes ya están precargados en cada hoja.
B7: 3. Registra la fecha de la sesión en la celda amarilla de la fila 3.
B8: 4. Durante la sesión, completa las 8 filas de TAREAS con el grupo: nombre de la tarea, frecuencia, tiempo actual en minutos, herramienta IA y tiempo proyectado con IA.
B9: 5. Las columnas AHORRO (min) y % REDUCCIÓN se calculan automáticamente.
B10: 6. El RESUMEN al final de cada hoja muestra: tareas mapeadas · horas/semana actuales · horas/semana con IA · ahorro semanal. Se calcula solo.
B11: 7. El RESUMEN GLOBAL se actualiza automáticamente con los datos de todas las hojas. Ese es el reporte para María Elvira.
B14: ⭕ Celdas AMARILLAS = las completas tú · Celdas VERDES = se calculan automáticamente · Resumen Global = se llena automáticamente

Sheet RESUMEN GLOBAL
B1: IAM Intelligence™ · Resumen de Productividad por Área · Comfacesar 2026
B3: ÁREA | C3: # FUNC | D3: TAREAS MAPEADAS | E3: HRS/SEM ACTUAL | F3: HRS/SEM CON IA | G3: AHORRO HRS/SEM | H3: % REDUCCIÓN
B4: COMUNICACIONES | C4: 5 | D4: =COMUNICACIONES!B25 -> 8 | E4: =COMUNICACIONES!D25 -> 51.25 | F4: =COMUNICACIONES!F25 -> 10.683333 | G4: =IFERROR(E4-F4,0) -> 40.566667 | H4: =IFERROR(IF(E4>0,(E4-F4)/E4,0),0) -> 0.79154472
B5: MERCADEO | C5: 3 | D5: =MERCADEO!B20 -> 0 | E5: =MERCADEO!D20 -> 0 | F5: =MERCADEO!F20 -> 0 | G5: =IFERROR(E5-F5,0) -> 0 | H5: =IFERROR(IF(E5>0,(E5-F5)/E5,0),0) -> 0
B6: AGENCIA DE EMPLEO | C6: 2 | D6: ='AGENCIA DE EMPLEO'!B20 -> 6 | E6: ='AGENCIA DE EMPLEO'!D20 -> 28.95 | F6: ='AGENCIA DE EMPLEO'!F20 -> 12.116667 | G6: =IFERROR(E6-F6,0) -> 16.833333 | H6: =IFERROR(IF(E6>0,(E6-F6)/E6,0),0) -> 0.58146229
B7: TALENTO HUMANO | C7: 2 | D7: ='TALENTO HUMANO'!B20 -> 1 | E7: ='TALENTO HUMANO'!D20 -> 0.33333333 | F7: ='TALENTO HUMANO'!F20 -> 0.05 | G7: =IFERROR(E7-F7,0) -> 0.28333333 | H7: =IFERROR(IF(E7>0,(E7-F7)/E7,0),0) -> 0.85
B8: PLANEACION | C8: 5 | D8: =PLANEACION!B20 -> 0 | E8: =PLANEACION!D20 -> 0 | F8: =PLANEACION!F20 -> 0 | G8: =IFERROR(E8-F8,0) -> 0 | H8: =IFERROR(IF(E8>0,(E8-F8)/E8,0),0) -> 0
B9: CONTABILIDAD | C9: 2 | D9: =CONTABILIDAD!B20 -> 4 | E9: =CONTABILIDAD!D20 -> 15 | F9: =CONTABILIDAD!F20 -> 3.75 | G9: =IFERROR(E9-F9,0) -> 11.25 | H9: =IFERROR(IF(E9>0,(E9-F9)/E9,0),0) -> 0.75
B10: TESORERIA | C10: 2 | D10: =TESORERIA!B20 -> 0 | E10: =TESORERIA!D20 -> 0 | F10: =TESORERIA!F20 -> 0 | G10: =IFERROR(E10-F10,0) -> 0 | H10: =IFERROR(IF(E10>0,(E10-F10)/E10,0),0) -> 0
B11: GERENCIA FINANCIERA | C11: 3 | D11: ='GERENCIA FINANCIERA'!B20 -> 0 | E11: ='GERENCIA FINANCIERA'!D20 -> 0 | F11: ='GERENCIA FINANCIERA'!F20 -> 0 | G11: =IFERROR(E11-F11,0) -> 0 | H11: =IFERROR(IF(E11>0,(E11-F11)/E11,0),0) -> 0
B12: SUB ADMIN FINANCIERA | C12: 2 | D12: ='SUB ADMIN FINANCIERA'!B20 -> 6 | E12: ='SUB ADMIN FINANCIERA'!D20 -> 10.916667 | F12: ='SUB ADMIN FINANCIERA'!F20 -> 0.83333333 | G12: =IFERROR(E12-F12,0) -> 10.083333 | H12: =IFERROR(IF(E12>0,(E12-F12)/E12,0),0) -> 0.92366412
B13: JURIDICA | C13: 2 | D13: =JURIDICA!B32 -> 19 | E13: =JURIDICA!D32 -> 96.833333 | F13: =JURIDICA!F32 -> 2.2333333 | G13: =IFERROR(E13-F13,0) -> 94.6 | H13: =IFERROR(IF(E13>0,(E13-F13)/E13,0),0) -> 0.97693632
B14: CUMPLIMIENTO | C14: 3 | D14: =CUMPLIMIENTO!B20 -> 1 | E14: =CUMPLIMIENTO!D20 -> 0.53333333 | F14: =CUMPLIMIENTO!F20 -> 0 | G14: =IFERROR(E14-F14,0) -> 0.53333333 | H14: =IFERROR(IF(E14>0,(E14-F14)/E14,0),0) -> 1
B15: SUB OPERATIVA | C15: 2 | D15: ='SUB OPERATIVA'!B20 -> 4 | E15: ='SUB OPERATIVA'!D20 -> 28.166667 | F15: ='SUB OPERATIVA'!F20 -> 1.3666667 | G15: =IFERROR(E15-F15,0) -> 26.8 | H15: =IFERROR(IF(E15>0,(E15-F15)/E15,0),0) -> 0.95147929
B16: TECNOLOGIA | C16: 1 | D16: =TECNOLOGIA!B20 -> 5 | E16: =TECNOLOGIA!D20 -> 2.1666667 | F16: =TECNOLOGIA!F20 -> 0.33333333 | G16: =IFERROR(E16-F16,0) -> 1.8333333 | H16: =IFERROR(IF(E16>0,(E16-F16)/E16,0),0) -> 0.84615385
B17: SUBSIDIO | C17: 3 | D17: =SUBSIDIO!B20 -> 4 | E17: =SUBSIDIO!D20 -> 75 | F17: =SUBSIDIO!F20 -> 4.0833333 | G17: =IFERROR(E17-F17,0) -> 70.916667 | H17: =IFERROR(IF(E17>0,(E17-F17)/E17,0),0) -> 0.94555556
B18: IPS | C18: 1 | D18: =IPS!B20 -> 1 | E18: =IPS!D20 -> 106.66667 | F18: =IPS!F20 -> 8 | G18: =IFERROR(E18-F18,0) -> 98.666667 | H18: =IFERROR(IF(E18>0,(E18-F18)/E18,0),0) -> 0.925
B19: PRESUPUESTO | C19: 1 | D19: =PRESUPUESTO!B20 -> 0 | E19: =PRESUPUESTO!D20 -> 0 | F19: =PRESUPUESTO!F20 -> 0 | G19: =IFERROR(E19-F19,0) -> 0 | H19: =IFERROR(IF(E19>0,(E19-F19)/E19,0),0) -> 0
B20: VIVIENDA | C20: 2 | D20: =VIVIENDA!B21 -> 8 | E20: =VIVIENDA!D21 -> 11.833333 | F20: =VIVIENDA!F21 -> 2.0833333 | G20: =IFERROR(E20-F20,0) -> 9.75 | H20: =IFERROR(IF(E20>0,(E20-F20)/E20,0),0) -> 0.82394366
B21: EDUCACION | C21: 2 | D21: =EDUCACION!B20 -> 0 | E21: =EDUCACION!D20 -> 0 | F21: =EDUCACION!F20 -> 0 | G21: =IFERROR(E21-F21,0) -> 0 | H21: =IFERROR(IF(E21>0,(E21-F21)/E21,0),0) -> 0
B22: SERVICIOS SOCIALES | C22: 2 | D22: ='SERVICIOS SOCIALES'!B31 -> 14 | E22: ='SERVICIOS SOCIALES'!D31 -> 346 | F22: ='SERVICIOS SOCIALES'!F31 -> 19.5 | G22: =IFERROR(E22-F22,0) -> 326.5 | H22: =IFERROR(IF(E22>0,(E22-F22)/E22,0),0) -> 0.94364162
B23: DIRECCION ADMIN | C23: 1 | D23: ='DIRECCION ADMIN'!B20 -> 0 | E23: ='DIRECCION ADMIN'!D20 -> 0 | F23: ='DIRECCION ADMIN'!F20 -> 0 | G23: =IFERROR(E23-F23,0) -> 0 | H23: =IFERROR(IF(E23>0,(E23-F23)/E23,0),0) -> 0
B24: CREDITO | C24: 1 | D24: =CREDITO!B20 -> 0 | E24: =CREDITO!D20 -> 0 | F24: =CREDITO!F20 -> 0 | G24: =IFERROR(E24-F24,0) -> 0 | H24: =IFERROR(IF(E24>0,(E24-F24)/E24,0),0) -> 0
B25: TOTAL COMFACESAR | D25: =SUM(D4:D24) -> 81 | E25: =SUM(E4:E24) -> 773.65 | F25: =SUM(F4:F24) -> 65.033333 | G25: =SUM(G4:G24) -> 708.61667 | H25: =SUM(H4:H24) -> 11.309381
B27: ⭕ Este resumen se actualiza automáticamente cada vez que completas una sesión de assessment. Compártelo con María Elvira al finalizar cada grupo.

Sheet JURIDICA
B2: IAM Intelligence™ · Assessment · JURIDICA
B4: Área: | C4: JURIDICA | E4: Fecha sesión: | H4: Sesión #:
B5: PARTICIPANTES
B6: ✓ Renata Del Mar Laino Niño | D6: ✓ Carlos Mario Gamarra Montes | F6: ✓ Lilibeth Del Carmen Costa Méndez
B9: DIAGNÓSTICO — TAREAS ACTUALES
B10: TAREA / REPORTE | C10: FRECUENCIA | D10: TIEMPO ACTUAL (minutos) | E10: HERRAMIENTA IA | F10: TIEMPO CON IA (minutos) | G10: AHORRO (min) | H10: % REDUCCIÓN | I10: AHORRO (HORAS) | J10: OBSERVACIONES
B11: Revisión de Solicitudes de elaboracion de convenios de prácticas para los estudiantes de INSTECOM | C11: Quincenal | D11: 30 | E11: Claude | F11: 4 | G11: =IFERROR(D11-F11,"") -> 26 | H11: =IFERROR(IF(D11>0,(D11-F11)/D11,0),"") -> 0.86666667 | I11: =IFERROR(G11/60,"") -> 0.43333333 | J11: Carlos Gamarra, antes de forma manual, leía la infomracion que esta en el formato, revisando que coinida con los documentos de la mepresa y la copia de la cedula, adicionamente los antecedentes. Y ademas crear el correo y enviarlo
B12: Revisión preliminar de convenios de prácticas con universidades a nivel nacional. | C12: Mensual | D12: 30 | E12: Claude | F12: 5 | G12: =IFERROR(D12-F12,"") -> 25 | H12: =IFERROR(IF(D12>0,(D12-F12)/D12,0),"") -> 0.83333333 | I12: =IFERROR(G12/60,"") -> 0.41666667 | J12: Carlos Gamarra, antes de forma manual, leía la infomracion que esta en el convenio, revisando que los datos de la caja y del director esten correctos y luego redactaba el correo al área jurídica donde comparto el documento para que sea revisado por los abogados.
B13: Revisión de contratos de bienestar con entidades públicas. | C13: Mensual | D13: 45 | E13: Claude | F13: 10 | G13: =IFERROR(D13-F13,"") -> 35 | H13: =IFERROR(IF(D13>0,(D13-F13)/D13,0),"") -> 0.77777778 | I13: =IFERROR(G13/60,"") -> 0.58333333 | J13: Carlos Gamarra, antes de forma manual, leía la infomracion que esta en el contrato y sus anexos, revisando que los datos de la caja y del director esten correctos, verificando que no exista riesgo para la caja y luego redactaba el correo al área jurídica donde comparto el documento para que sea revisado por los abogados.
B14: Revisión de formatos de inscripción de proveedores. | C14: Ocasional | D14: 15 | E14: Claude | F14: 3 | G14: =IFERROR(D14-F14,"") -> 12 | H14: =IFERROR(IF(D14>0,(D14-F14)/D14,0),"") -> 0.8 | I14: =IFERROR(G14/60,"") -> 0.2 | J14: Carlos Gamarra, antes de forma manual, leía la infomracion que esta en el formato, revisando que los datos de la caja y del director esten correctos.
B15: Revisión de solicitudes de elaboración de convenios de descuentos. | C15: Mensual | D15: 30 | E15: Claude | F15: 5 | G15: =IFERROR(D15-F15,"") -> 25 | H15: =IFERROR(IF(D15>0,(D15-F15)/D15,0),"") -> 0.83333333 | I15: =IFERROR(G15/60,"") -> 0.41666667 | J15: Carlos Gamarra, antes de forma manual, leía la infomracion que esta en la solicitud de elaboración del convenio, revisando que los datos de la empresa aliada y su representante legal esten correctos y luego redactaba el correo al área jurídica donde comparto el paquete de documentos para que sea elaborado el convenio por los abogados.
B16: Revisión de solicitudes de elaboración de convenios de marcos y sus anexos. | C16: Mensual | D16: 30 | E16: Claude | F16: 10 | G16: =IFERROR(D16-F16,"") -> 20 | H16: =IFERROR(IF(D16>0,(D16-F16)/D16,0),"") -> 0.66666667 | I16: =IFERROR(G16/60,"") -> 0.33333333 | J16: Carlos Gamarra, antes de forma manual, leía la infomracion que esta en la solicitud de elaboración del convenio, revisando que los datos de la empresa aliada y su representante legal esten correctos y luego redactaba el correo al área jurídica donde comparto el paquete de documentos para que sea elaborado el convenio por los abogados.
B17: Consolidación trimestral del informe de sostenibilidad. | C17: Ocasional | D17: 30 | E17: Claude | F17: 8 | G17: =IFERROR(D17-F17,"") -> 22 | H17: =IFERROR(IF(D17>0,(D17-F17)/D17,0),"") -> 0.73333333 | I17: =IFERROR(G17/60,"") -> 0.36666667 | J17: Carlos Gamarra, antes de forma manual, leía la infomracion consignada en cada convenio paa conocer a poblacion beneficiada y de esta forma poder consolidar los datos que solicita el informe. Luego redacto un correo al área responsable para compartir la información
B18: Revisión RequisitosLegales Contratación | C18: Diaria | D18: 20 | E18: Claude | F18: 4 | G18: =IFERROR(D18-F18,"") -> 16 | H18: =IFERROR(IF(D18>0,(D18-F18)/D18,0),"") -> 0.8 | I18: =IFERROR(G18/60,"") -> 0.26666667 | J18: Renata: A través de un buscador web se consulta la normatividad aplicable y se contrasta con lo dispuesto en las políticas de la Caja
B19: Revisión Minutas Contractuales | C19: Diaria | D19: 30 | E19: Claude | F19: 5 | G19: =IFERROR(D19-F19,"") -> 25 | H19: =IFERROR(IF(D19>0,(D19-F19)/D19,0),"") -> 0.83333333 | I19: =IFERROR(G19/60,"") -> 0.41666667 | J19: Renata: Se revisan los datos incluidos en las minutas contractuales de forma física, comparandolos con los datos de la solicitud y la propuesta.
B20: Informe Alta Gerencia | C20: Trimestral | D20: 960 | E20: Claude | F20: 10 | G20: =IFERROR(D20-F20,"") -> 950 | H20: =IFERROR(IF(D20>0,(D20-F20)/D20,0),"") -> 0.98958333 | I20: =IFERROR(G20/60,"") -> 15.833333 | J20: Lilibeth Costa: Consolidacion, analisis de data de mas de 20 procesos internos organizados por Google Sheets
B21: Informe Comite Juridico | C21: Mensual | D21: 480 | E21: Claude | F21: 10 | G21: =IFERROR(D21-F21,"") -> 470 | H21: =IFERROR(IF(D21>0,(D21-F21)/D21,0),"") -> 0.97916667 | I21: =IFERROR(G21/60,"") -> 7.8333333 | J21: Lilibeth Costa: Consolidacion, analisis de data de mas de 20 procesos internos organizados por Google Sheets
B22: Seguimiento Asistentes Juridicos | C22: Diaria | D22: 60 | E22: Claude | F22: 5 | G22: =IFERROR(D22-F22,"") -> 55 | H22: =IFERROR(IF(D22>0,(D22-F22)/D22,0),"") -> 0.91666667 | I22: =IFERROR(G22/60,"") -> 0.91666667 | J22: Lilibeth Costa: Pendientes por elaborar, estado actual y KPIS del equipo
... B30: Presentación institucional de informes a entes de control | C30: Ocasional | D30: 480 | E30: Claude | F30: 10 | G30: =IFERROR(D30-F30,"") | H30: =IFERROR(IF(D30>0,(D30-F30)/D30,0),"") | I30: =IFERROR(G30/60,"") | J30: Lo registró Lucía el 9 de octubre de 2026 a partir del acta de la Sesión 11 del 24 de septiembre de 2026. Hacerla a mano toma una jornada de trabajo completa, 480 minutos. Se subió la presentación que la oficina viene usando desde hace años, se pidió actualizarla y salió en unos diez minutos, explicando además qué había cambiado. Se usó esa misma tarde en una reunión con varias áreas. Queda como Ocasional porque el acta no dice cada cuánto se presenta a los entes de control.
B31: RESUMEN DE PRODUCTIVIDAD — RESULTADO DEL ASSESSMENT
B32: =COUNTA(B11:B30) | D32: =IFERROR(SUM(D11:D30)/60,0) | F32: =IFERROR(SUM(F11:F30)/60,0) | H32: =IFERROR((SUM(D11:D30)-SUM(F11:F30))/60,0)
B33: TAREAS MAPEADAS | D33: HRS/SEM ACTUAL | F33: HRS/SEM CON IA | H33: AHORRO HRS/SEM
B34: ⭕ Los datos de esta hoja se reflejan automáticamente en el RESUMEN GLOBAL. Comparte esa hoja con María Elvira.

Sheet SERVICIOS SOCIALES
B1: IAM Intelligence™ · Assessment · SERVICIOS SOCIALES
B3: Área: | C3: SERVICIOS SOCIALES | E3: Fecha sesión: | H3: Sesión #:
B4: PARTICIPANTES
B5: ✓ Lilian Paola Ramos | F5: ✓ Juan Pablo Cúrvelo
B8: DIAGNÓSTICO — TAREAS ACTUALES
B9: TAREA / REPORTE | C9: FRECUENCIA | D9: TIEMPO ACTUAL (minutos) | E9: HERRAMIENTA IA | F9: TIEMPO CON IA (minutos) | G9: AHORRO (min) | H9: % REDUCCIÓN | I9: AHORRO (HORAS) | J9: OBSERVACIONES
B10: Presentación resultado MMI Consejo Directivo | C10: Ocasional | D10: 960 | E10: Claude | F10: 240 | G10: =IFERROR(D10-F10,"") -> 720 | H10: =IFERROR(IF(D10>0,(D10-F10)/D10,0),"") -> 0.75 | I10: =IFERROR(G10/60,"") -> 12 | J10: JP:Buen ejercicio, para hacer comparativo entre años.
B11: Respuesta a anotacion 06 Auditoria Interna | C11: Ocasional | D11: 3840 | E11: Claude | F11: 240 | G11: =IFERROR(D11-F11,"") -> 3600 | H11: =IFERROR(IF(D11>0,(D11-F11)/D11,0),"") -> 0.9375 | I11: =IFERROR(G11/60,"") -> 60 | J11: JP:Este ejercicio nos permitió organizar de una forma mejor la respuesta ante un requerimiento de Auditoria Interna por alguna observación a los servicios.
B12: Elaboracion de Actas de Contratos | C12: Ocasional | D12: 120 | E12: Claude | F12: 30 | G12: =IFERROR(D12-F12,"") -> 90 | H12: =IFERROR(IF(D12>0,(D12-F12)/D12,0),"") -> 0.75 | I12: =IFERROR(G12/60,"") -> 1.5 | J12: JP: este ejercicio me permitió optimizar el triempo de elaboración de las actas de inicio, recibo y liquidación de los contratos del area.
B13: Revision de Actas de Contratos | C13: Ocasional | D13: 480 | E13: Claude | F13: 30 | G13: =IFERROR(D13-F13,"") -> 450 | H13: =IFERROR(IF(D13>0,(D13-F13)/D13,0),"") -> 0.9375 | I13: =IFERROR(G13/60,"") -> 7.5 | J13: JP: con este ejercicio se reduce a 0 errores al momento de revisar las actas elaboradas en la Coordinación de Rec y Deportes antes de pasar a firma.
B14: Informe de Sostenibilidad C.C. Crispin Villazon de Armas | C14: Ocasional | D14: 480 | E14: Claude | F14: 60 | G14: =IFERROR(D14-F14,"") -> 420 | H14: =IFERROR(IF(D14>0,(D14-F14)/D14,0),"") -> 0.875 | I14: =IFERROR(G14/60,"") -> 7 | J14: JP: en este ejercicio se organizó un informe sobre el comportamiento financiero y de Usos que ha tenido el CC Crispin Villazon de Armas, arrojando datos financieros y acciones comerciales sugeridas por implementar.
B15: Informe de Seguimiento No 4 CCF015-05-00046 "Proyecto Construccion De Cubierta Para Cancha Sintetica Complejo Deportivo" | C15: Mensual | D15: 1440 | E15: Claude | F15: 240 | G15: =IFERROR(D15-F15,"") -> 1200 | H15: =IFERROR(IF(D15>0,(D15-F15)/D15,0),"") -> 0.83333333 | I15: =IFERROR(G15/60,"") -> 20 | J15: JP: con este primer ejercicio de AGENTE INFRA se aprendió a crear un entorno donde con trazando una ruta de un proceso y dandole la ruta donde encontrar la información, actaulizó de manera automatizada la ficha de seguimiento a los proyectos de infraestructura asignado a la Gerencia de SS.
B16: Acta de Cierre-FP-06 CCF015-05-00039 C.R. La Pedregosa | C16: Ocasional | D16: 720 | E16: Claude | F16: 60 | G16: =IFERROR(D16-F16,"") -> 660 | H16: =IFERROR(IF(D16>0,(D16-F16)/D16,0),"") -> 0.91666667 | I16: =IFERROR(G16/60,"") -> 11 | J16: JP: aplicando la estructura a la herramienta de AGENTE nos permitio elaborar en menor tiempo un acta de cierre de un proyecto de infraestructura.
B17: Informe de Seguimiento No 12 CCF015-05-00033 "Proyecto Ampliación Cobertura - Segunda Etapa Centro Recreacional Buenavista - Pueblo Bello" | C17: Mensual | D17: 1440 | E17: Claude | F17: 45 | G17: =IFERROR(D17-F17,"") -> 1395 | H17: =IFERROR(IF(D17>0,(D17-F17)/D17,0),"") -> 0.96875 | I17: =IFERROR(G17/60,"") -> 23.25 | J17: JP: Se uso el AGENTE INFRA y actualizó de forma inmediata la ficha de seguimiento del proyecto en mensión.
B18: Diligenciamiento del formato FP-03 para el Proyecto CCF015-05-00039 C.R. La Pedregosa | C18: Ocasional | D18: 240 | E18: Claude | F18: 60 | G18: =IFERROR(D18-F18,"") -> 180 | H18: =IFERROR(IF(D18>0,(D18-F18)/D18,0),"") -> 0.75 | I18: =IFERROR(G18/60,"") -> 3 | J18: JP: se elaboro con la herramienta el diligenciamineto del formato del Plan de Diseño del proyecto em mensión.
B19: Diligenciamiento del formato FP-03 para el Proyecto CCF015-05-00046 Cubierta Cancha Sintetica | C19: Ocasional | D19: 240 | E19: Claude | F19: 30 | G19: =IFERROR(D19-F19,"") -> 210 | H19: =IFERROR(IF(D19>0,(D19-F19)/D19,0),"") -> 0.875 | I19: =IFERROR(G19/60,"") -> 3.5 | J19: JP: se elaboro con la herramienta el diligenciamineto del formato del Plan de Diseño del proyecto em mensión.
B20: Analisis Comparativo C.C.T. Vs Propuesta Admon | C20: Ocasional | D20: 7200 | E20: Claude | F20: 45 | G20: =IFERROR(D20-F20,"") -> 7155 | H20: =IFERROR(IF(D20>0,(D20-F20)/D20,0),"") -> 0.99375 | I20: =IFERROR(G20/60,"") -> 119.25 | J20: JP: se necesitaba cruzar la CCT actual contra la Propuesta de la Admon para saber coincidencias, diferencias que nos permitan tener un panorama mas claropra la toma de desiciones y elaborar una contra propuesta.
B21: Respuesta a Recomendacion No 11 Visita Ordinaria SuperSubsidio 2026 | C21: Ocasional | D21: 480 | E21: Claude | F21: 30 | G21: =IFERROR(D21-F21,"") -> 450 | H21: =IFERROR(IF(D21>0,(D21-F21)/D21,0),"") -> 0.9375 | I21: =IFERROR(G21/60,"") -> 7.5 | J21: JP: Se estructuro la respuesta a la Recomendaccion con su respectiva Acción de Mejora y las actividades que se contemplan para cumplir y subsanar la recomendación.
... B23: Informe De Gestion Tercer Trimestre Gerencia De Serv Sociales 2026 | C23: Trimestral | D23: 720 | E23: Claude | F23: 30 | G23: =IFERROR(D23-F23,"") -> 690 | H23: =IFERROR(IF(D23>0,(D23-F23)/D23,0),"") -> 0.95833333 | I23: =IFERROR(G23/60,"") -> 11.5 | J23: JP: Consolidacion de reportes de Gestion de cada uno de los Servicios de la Gerencia.
G24: =IFERROR(D24-F24,"") -> 0 | H24: =IFERROR(IF(D24>0,(D24-F24)/D24,0),"") -> 0 | I24: =IFERROR(G24/60,"") -> 0
G25: =IFERROR(D25-F25,"") -> 0 | H25: =IFERROR(IF(D25>0,(D25-F25)/D25,0),"") -> 0 | I25: =IFERROR(G25/60,"") -> 0
G26: =IFERROR(D26-F26,"") -> 0 | H26: =IFERROR(IF(D26>0,(D26-F26)/D26,0),"") -> 0 | I26: =IFERROR(G26/60,"") -> 0
G27: =IFERROR(D27-F27,"") -> 0 | H27: =IFERROR(IF(D27>0,(D27-F27)/D27,0),"") -> 0 | I27: =IFERROR(G27/60,"") -> 0
G28: =IFERROR(D28-F28,"") -> 0 | H28: =IFERROR(IF(D28>0,(D28-F28)/D28,0),"") -> 0 | I28: =IFERROR(G28/60,"") -> 0
B30: RESUMEN DE PRODUCTIVIDAD — RESULTADO DEL ASSESSMENT
B31: =COUNTA(B10:B28) -> 14 | D31: =IFERROR(SUM(D10:D28)/60,0) -> 346 | F31: =IFERROR(SUM(F10:F28)/60,0) -> 19.5 | H31: =IFERROR((SUM(D10:D28)-SUM(F10:F28))/60,0) -> 326.5
B32: TAREAS MAPEADAS | D32: HRS/SEM ACTUAL | F32: HRS/SEM CON IA | H32: AHORRO HRS/SEM
B33: ⭕ Los datos de esta hoja se reflejan automáticamente en el RESUMEN GLOBAL. Comparte esa hoja con María Elvira.

Sheet VIVIENDA
B1: IAM Intelligence™ · Assessment · VIVIENDA
B3: Área: | C3: VIVIENDA | E3: Fecha sesión: | F3: 13 de agosto | H3: Sesión #: | I3: 1
B4: PARTICIPANTES
B5: ✓ Deimer Pérez | D5: ✓ Cindy Silva
B8: DIAGNÓSTICO — TAREAS ACTUALES
B9: TAREA / REPORTE | C9: FRECUENCIA | D9: TIEMPO ACTUAL (minutos) | E9: HERRAMIENTA IA | F9: TIEMPO CON IA (minutos) | G9: AHORRO (min) | H9: % REDUCCIÓN | I9: AHORRO (HORAS) | J9: OBSERVACIONES
B10: Seguimiento a ejecución técnica y jurídica Mejoramiento Rural | C10: Semanal | D10: 60 | E10: Claude | F10: 15 | G10: =IFERROR(D10-F10,"") -> 45 | H10: =IFERROR(IF(D10>0,(D10-F10)/D10,0),"") -> 0.75 | I10: =IFERROR(G10/60,"") -> 0.75 | J10: Auxiliar de vivienda, el seguimiento eracompletamente manual y existia la posibilidad que las evidencias del proceso no se documentaran de manera adecuada.
B11: seguimiento y notificación a vencimiento del SFV | C11: Quincenal | D11: 60 | E11: Claude | F11: 15 | G11: =IFERROR(D11-F11,"") -> 45 | H11: =IFERROR(IF(D11>0,(D11-F11)/D11,0),"") -> 0.75 | I11: =IFERROR(G11/60,"") -> 0.75 | J11: Auxiliar de vivienda y coor vivienda, El seguimieto era manual y exitia la posibilidad que algun beneficiario no quedara incluido en el acta de prorrogas y posteriormente sus ubsidio reitegrado
B12: Seguimiento y reporte a Quejas, DP, tutela, Comunicaciones internas | C12: Diaria | D12: 60 | E12: Claude | F12: 15 | G12: =IFERROR(D12-F12,"") -> 45 | H12: =IFERROR(IF(D12>0,(D12-F12)/D12,0),"") -> 0.75 | I12: =IFERROR(G12/60,"") -> 0.75 | J12: Auxiliar de vivienda, No exitia un seguimiento a las respuesta de PQR y fechas en las que se identificara vencimiento de termino de manera clara y precisa.
B13: Ejecución ficha Tecnica Urbano | C13: Mensual | D13: 70 | E13: Claude | F13: 10 | G13: =IFERROR(D13-F13,"") -> 60 | H13: =IFERROR(IF(D13>0,(D13-F13)/D13,0),"") -> 0.85714286 | I13: =IFERROR(G13/60,"") -> 1 | J13: Aux Vivienda, y coor Fovis se hacia de manera manual y dependia del auxiliar de vivienda la información, hoy ya esta consolidad y cualquier funcionario podria emitir la ficha Técnica
B14: Ejecución Ficha Técnica Rural | C14: Mensual | D14: 70 | E14: Claude | F14: 10 | G14: =IFERROR(D14-F14,"") -> 60 | H14: =IFERROR(IF(D14>0,(D14-F14)/D14,0),"") -> 0.85714286 | I14: =IFERROR(G14/60,"") -> 1 | J14: Aux Vivienda, y coor Fovis se hacia de manera manual y dependia del auxiliar de vivienda la información, hoy ya esta consolidad y cualquier funcionario podria emitir la ficha Técnica
B15: Planeador Activides Generales Area | C15: Diaria | D15: 60 | E15: Claude | F15: 15 | G15: =IFERROR(D15-F15,"") -> 45 | H15: =IFERROR(IF(D15>0,(D15-F15)/D15,0),"") -> 0.75 | I15: =IFERROR(G15/60,"") -> 0.75 | J15: Aux Vivienda, y coor Fovis se hacia de manera manual y realizar segimeinto a la ejecución era una actividad dificil de controlar
B16: Data de informe de Gestion trimestral | C16: Mensual | D16: 90 | E16: Claude | F16: 30 | G16: =IFERROR(D16-F16,"") -> 60 | H16: =IFERROR(IF(D16>0,(D16-F16)/D16,0),"") -> 0.66666667 | I16: =IFERROR(G16/60,"") -> 1 | J16: Aux Vivienda, y coor Fovis se hacia de manera manual y dependia del auxiliar de vivienda la información, hoy ya esta consolidad y cualquier funcionario podria emitir el informe de Gestión de Calidad con los datos actualizados
B17: Analisis a nuevas normas y actualizaciones de las mismas en el Sector Vivienda | C17: Diaria | D17: 240 | E17: Claude | F17: 15 | G17: =IFERROR(D17-F17,"") -> 225 | H17: =IFERROR(IF(D17>0,(D17-F17)/D17,0),"") -> 0.9375 | I17: =IFERROR(G17/60,"") -> 3.75 | J17: Coor Fovis se hacia de manera manual, el tiempo que implicaba analizar la normatividad actualizada era muy grande, hoy se pueden hacer analisis comparativo en tiempo corto
B18: Presentacion de Gestion General a Nivel Gerencial | C18: Semanal | D18: 120 | E18: Claude | F18: 15 | G18: =IFERROR(D18-F18,"") -> 105 | H18: =IFERROR(IF(D18>0,(D18-F18)/D18,0),"") -> 0.875 | I18: =IFERROR(G18/60,"") -> 1.75 | J18: Coor. Fovis, se hacia de manera manual y visualmente profesional
B20: RESUMEN DE PRODUCTIVIDAD — RESULTADO DEL ASSESSMENT
B21: =COUNTA(B10:B18) | D21: =IFERROR(SUM(D10:D18)/60,0) | F21: =IFERROR(SUM(F10:F18)/60,0) | H21: =IFERROR((SUM(D10:D18)-SUM(F10:F18))/60,0)
B22: TAREAS MAPEADAS | D22: HRS/SEM ACTUAL | F22: HRS/SEM CON IA | H22: AHORRO HRS/SEM
B23: ⭕ Los datos de esta hoja se reflejan automáticamente en el RESUMEN GLOBAL. Comparte esa hoja con María Elvira.

Sheet SUB ADMIN FINANCIERA
B1: IAM Intelligence™ · Assessment · SUB ADMIN FINANCIERA
B3: Área: | C3: SUB ADMIN FINANCIERA | E3: Fecha sesión: | H3: Sesión #:
B4: PARTICIPANTES
B5: ✓ Rafael José Solano Fernández | D5: ✓ Liliany Lineth Gómez Zuleta
B8: DIAGNÓSTICO — TAREAS ACTUALES
B9: TAREA / REPORTE | C9: FRECUENCIA | D9: TIEMPO ACTUAL (minutos) | E9: HERRAMIENTA IA | F9: TIEMPO CON IA (minutos) | G9: AHORRO (min) | H9: % REDUCCIÓN | I9: AHORRO (HORAS) | J9: OBSERVACIONES
B10: Pre Validacion precontractual | C10: Diaria | D10: 480 | E10: Claude | F10: 30 | G10: =IFERROR(D10-F10,"") -> 450 | H10: =IFERROR(IF(D10>0,(D10-F10)/D10,0),"") -> 0.9375 | I10: =IFERROR(G10/60,"") -> 7.5 | J10: Rafael S: Anteriormente, esta actividad me tomaba aproximadamente un día laboral, debido al tiempo requerido para analizar la documentación, verificar la formalidad de la solicitud de elaboración del contrato y realizar la revisión de los documentos y requisitos establecidos para la contratación. Este proceso implicaba validar integralmente la información antes de otorgar la aprobación correspondiente.
B11: Automatizacion de correo cuyo asunto: requeriminetos para aprobacion y asigancion de ODR | C11: Diaria | D11: 60 | E11: Claude | F11: 10 | G11: =IFERROR(D11-F11,"") -> 50 | H11: =IFERROR(IF(D11>0,(D11-F11)/D11,0),"") -> 0.83333333 | I11: =IFERROR(G11/60,"") -> 0.83333333 | J11: Rafael S: Anteriormente, dentro del proceso de revisión, me correspondía validar la información contenida en el cuerpo del correo y verificar la propuesta o cotización adjunta. Esta revisión se mantiene, teniendo en cuenta que la aprobación del requerimiento corresponde a mi gestión. Sin embargo, durante la validación se pueden identificar diferentes situaciones que requieren corrección o aclaración, como inconsistencias entre el objeto del requerimiento y las actividades registradas en el RUT y la Cámara de Comercio, información faltante o cualquier otra observación relacionada con la documentación presentada. Por lo anterior, el propósito es que, mediante la automatización, estas situaciones puedan ser identificadas y gestionadas de manera más eficiente, reduciendo reprocesos y facilitando la revisión previa a la aprobación del requerimiento.
B12: Automatización del correo de solicitud de asignación de origen de recursos a la Gerencia Financiera, con revisión y adjunto de los documentos soporte como control del proceso y registro automático de la información en la matriz de seguimiento precontractual. Esta mejora facilita la trazabilidad y reduce los tiempos de gestión. | C12: Diaria | D12: 15 | E12: Claude | F12: 3 | G12: =IFERROR(D12-F12,"") -> 12 | H12: =IFERROR(IF(D12>0,(D12-F12)/D12,0),"") -> 0.8 | I12: =IFERROR(G12/60,"") -> 0.2 | J12: Rafael S: Anteriormente, el proceso se realizaba de manera más manual, ya que debía preparar los textos para copiar y pegar la información en el cuerpo del correo, consultar el archivo de Excel y trasladar nuevamente los datos. Estas actividades implicaban mayor tiempo y trabajo operativo. Con la automatización del correo dirigido a la Gerencia Financiera, cuyo asunto es “Precontractual – Solicitud de asignación de origen de recursos”, se genera automáticamente un texto predeterminado, diseñado por mí y posteriormente mejorado en su formato a solicitud mía. Como parte del control del proceso, desde nuestra área revisamos el contenido generado y adjuntamos el documento soporte correspondiente, ya sea la cotización o la propuesta. De manera simultánea, la automatización incorpora la información en la “Matriz de control y seguimiento precontractual”, lo que facilita el registro y seguimiento de los requerimientos, mejora la eficiencia del proceso y reduce el tiempo dedicado a tareas manuales.
B13: Automatización de textos de notificación del proceso precontractual. | C13: Diaria | D13: 10 | E13: Claude | F13: 3 | G13: =IFERROR(D13-F13,"") -> 7 | H13: =IFERROR(IF(D13>0,(D13-F13)/D13,0),"") -> 0.7 | I13: =IFERROR(G13/60,"") -> 0.11666667 | J13: Rafael S: Anteriormente, una vez recibida la comunicación de la Gerencia Financiera con la asignación del origen de los recursos, la Oficina Precontractual enviaba una notificación al área u oficina que había presentado el requerimiento, con el propósito de que el funcionario responsable conociera el estado y avance de su solicitud. Para ello, se contaba con dos textos de notificación, según la cuantía y el tipo de trámite: órdenes de compra y/o servicios o contratos. Estas comunicaciones permitían mantener informado al responsable sobre el avance del proceso. En el marco de la automatización, se dispuso mejorar ambos formatos para fortalecer la claridad y uniformidad de las comunicaciones. Asimismo, se indicó tener en cuenta el cuadro de cuantías y requisitos como herramienta de consulta para orientar la revisión y la toma de decisiones, de acuerdo con las condiciones aplicables a cada requerimiento.
B14: Se implementó la automatización para la elaboración de los formatos de Órdenes de Compra y Servicios. | C14: Diaria | D14: 30 | E14: Claude | F14: 3 | G14: =IFERROR(D14-F14,"") -> 27 | H14: =IFERROR(IF(D14>0,(D14-F14)/D14,0),"") -> 0.9 | I14: =IFERROR(G14/60,"") -> 0.45 | J14: Rafael S: Anteriormente, el proceso se realizaba de manera manual tomabamos el formato de ordenes y tocaba diligenciar la informacion requerida , ahora Cuando la Oficina de Gerencia Financiera remite el correo mediante el cual se aprueba y asigna el origen de los recursos, la herramienta identifica automáticamente la cuantía correspondiente para determinar si el trámite corresponde a una orden, identifica el área responsable del requerimiento y, con base en esta información, diligencia automáticamente el formato establecido para la orden de compra y/o servicio. Esto permite reducir actividades manuales, agilizar la elaboración del documento y mantener la estructura estandarizada definida para este tipo de trámites.
B15: Implementación el Portal de Control Precontractual (Dashboard) | C15: Mensual | D15: 60 | E15: Claude | F15: 1 | G15: =IFERROR(D15-F15,"") -> 59 | H15: =IFERROR(IF(D15>0,(D15-F15)/D15,0),"") -> 0.98333333 | I15: =IFERROR(G15/60,"") -> 0.98333333 | J15: Rafael S.: Anteriormente, el proceso se realizaba de manera manual, mediante la elaboración de informes mensuales y el registro y actualización de la información en archivos de Excel. Con la implementación del Dashboard automatizado, ahora contamos con la información disponible diariamente y en tiempo real, lo que facilita el seguimiento, la consulta y el análisis de la gestión sin tener que esperar al cierre mensual para consolidar la información.
G16: =IFERROR(D16-F16,"") -> 0 | H16: =IFERROR(IF(D16>0,(D16-F16)/D16,0),"") -> 0
G17: =IFERROR(D17-F17,"") -> 0 | H17: =IFERROR(IF(D17>0,(D17-F17)/D17,0),"") -> 0
B19: RESUMEN DE PRODUCTIVIDAD — RESULTADO DEL ASSESSMENT
B20: =COUNTA(B10:B17) -> 6 | D20: =IFERROR(SUM(D10:D17)/60,0) -> 10.916667 | F20: =IFERROR(SUM(F10:F17)/60,0) -> 0.83333333 | H20: =IFERROR((SUM(D10:D17)-SUM(F10:F17))/60,0) -> 10.083333
B21: TAREAS MAPEADAS | D21: HRS/SEM ACTUAL | F21: HRS/SEM CON IA | H21: AHORRO HRS/SEM
B22: ⭕ Los datos de esta hoja se reflejan automáticamente en el RESUMEN GLOBAL. Comparte esa hoja con María Elvira.

Sheet TECNOLOGIA
B1: IAM Intelligence™ · Assessment · TECNOLOGIA
B3: Área: | C3: TECNOLOGIA | E3: Fecha sesión: | H3: Sesión #:
B4: PARTICIPANTES
B5: ✓ Olga Lucía Barros Zuleta
B8: DIAGNÓSTICO — TAREAS ACTUALES
B9: TAREA / REPORTE | C9: FRECUENCIA | D9: TIEMPO ACTUAL (minutos) | E9: HERRAMIENTA IA | F9: TIEMPO CON IA (minutos) | G9: AHORRO (min) | H9: % REDUCCIÓN | I9: AHORRO (HORAS) | J9: OBSERVACIONES
B10: Revisión de las propuestas de TI y SI para realizar las Solicitudes de elaboracion de contratos. | C10: Ocasional | D10: 30 | E10: Claude | F10: 3 | G10: =IFERROR(D10-F10,"") -> 27 | H10: =IFERROR(IF(D10>0,(D10-F10)/D10,0),"") -> 0.9 | I10: =IFERROR(G10/60,"") -> 0.45 | J10: Se revisa que le valor, el objeto de la propuesta, los tiempos de vigencia esten acorde con las necesidades de la caja de compensacion.
B11: Diligenciar el formato de soliictud de contrato o de orden de compra o de servicios. | C11: Ocasional | D11: 20 | E11: Claude | F11: 5 | G11: =IFERROR(D11-F11,"") -> 15 | H11: =IFERROR(IF(D11>0,(D11-F11)/D11,0),"") -> 0.75 | I11: =IFERROR(G11/60,"") -> 0.25 | J11: Revisar que la propuesta este bien diligenciada en los formatos y que los datos esten correctamente.
B12: Realizar alertas para notificar los tiempos en que se termina la videncia de un contrato o una orden de servicio o de compra | C12: Ocasional | D12: 20 | E12: Claude | F12: 5 | G12: =IFERROR(D12-F12,"") -> 15 | H12: =IFERROR(IF(D12>0,(D12-F12)/D12,0),"") -> 0.75 | I12: =IFERROR(G12/60,"") -> 0.25 | J12: Agiliza el proceso de renovacion de los contratos y las ordenes, ya que con este control nos puede avisar con tiempo par ir adelantando la solicitud de las propuestas a los proveedores.
B13: realizar analisis de ejecucion de los contratos y de las ordenes de compra y servicio | C13: Ocasional | D13: 30 | E13: Claude | F13: 5 | G13: =IFERROR(D13-F13,"") -> 25 | H13: =IFERROR(IF(D13>0,(D13-F13)/D13,0),"") -> 0.83333333 | I13: =IFERROR(G13/60,"") -> 0.41666667 | J13: agiliza el proceso de manera detallada dandome resultados claro de todos los avances ejecutados de dicho contrato y ordenes de servicios, usando los tableros interactivos, es una manera muy clara de anilisara los avances de cada uno de los contratos
B14: revisar los correos que llegan de parte del gerente de tecnologia solicitando la elaboracion de solicitud de contratos y oredenes, dandole pronta respuestas para continuar con los tramites pertinentes para su elaboracion. | C14: Ocasional | D14: 30 | E14: Claude | F14: 2 | G14: =IFERROR(D14-F14,"") -> 28 | H14: =IFERROR(IF(D14>0,(D14-F14)/D14,0),"") -> 0.93333333 | I14: =IFERROR(G14/60,"") -> 0.46666667 | J14: realizando agentes donde se filtra el correo por llegada a la bandeja de entrada se le puede dar una respuesta pronta a la solicitud realizada por parte del Gerente de Tecnologia.
G15: =IFERROR(D15-F15,"") -> 0 | H15: =IFERROR(IF(D15>0,(D15-F15)/D15,0),"") -> 0
G16: =IFERROR(D16-F16,"") -> 0 | H16: =IFERROR(IF(D16>0,(D16-F16)/D16,0),"") -> 0
G17: =IFERROR(D17-F17,"") -> 0 | H17: =IFERROR(IF(D17>0,(D17-F17)/D17,0),"") -> 0
B19: RESUMEN DE PRODUCTIVIDAD — RESULTADO DEL ASSESSMENT
B20: =COUNTA(B10:B17) -> 5 | D20: =IFERROR(SUM(D10:D17)/60,0) -> 2.1666667 | F20: =IFERROR(SUM(F10:F17)/60,0) -> 0.33333333 | H20: =IFERROR((SUM(D10:D17)-SUM(F10:F17))/60,0) -> 1.8333333
B21: TAREAS MAPEADAS | D21: HRS/SEM ACTUAL | F21: HRS/SEM CON IA | H21: AHORRO HRS/SEM
B22: ⭕ Los datos de esta hoja se reflejan automáticamente en el RESUMEN GLOBAL. Comparte esa hoja con María Elvira.

Sheet COMUNICACIONES
B1: IAM Intelligence™ · Assessment · COMUNICACIONES
B3: Área: | C3: COMUNICACIONES | E3: Fecha sesión: | F3: 11 de agosto 2026 | H3: Sesión #: | I3: 1
B4: PARTICIPANTES
B5: ✓ María Elvira Marulanda Fernández | D5: ✓ Vidiana Bendeck Rueda | F5: ✓ Sandra Machado Arquez | H5: ✓ César Reyes Jiménez
B6: ✓ José Manuel Vergara Daza
B8: DIAGNÓSTICO — TAREAS ACTUALES
B9: TAREA / REPORTE | C9: FRECUENCIA | D9: TIEMPO ACTUAL (minutos) | E9: HERRAMIENTA IA | F9: TIEMPO CON IA (minutos) | G9: AHORRO (min) | H9: % REDUCCIÓN | I9: AHORRO (HORAS) | J9: OBSERVACIONES
B10: Actas y compromisos - Comité de tráfico | C10: Semanal | D10: 120 | E10: Claude | F10: 5 | G10: =IFERROR(D10-F10,"") -> 115 | H10: =IFERROR(IF(D10>0,(D10-F10)/D10,0),"") -> 0.95833333 | I10: =IFERROR(G10/60,"") -> 1.9166667 | J10: Diligenciar : Nombre de la persona mas el proceso antes de IA
B11: Producción de pieza gráfica para canales internos | C11: Semanal | D11: 480 | E11: Claude | F11: 25 | G11: =IFERROR(D11-F11,"") -> 455 | H11: =IFERROR(IF(D11>0,(D11-F11)/D11,0),"") -> 0.94791667 | I11: =IFERROR(G11/60,"") -> 7.5833333 | J11: Diligenciar : Nombre de la persona mas el proceso antes de IA
B12: Encuestas de percepción de valores y canales internos. | C12: Ocasional | D12: 120 | E12: Claude | F12: 30 | G12: =IFERROR(D12-F12,"") -> 90 | H12: =IFERROR(IF(D12>0,(D12-F12)/D12,0),"") -> 0.75 | I12: =IFERROR(G12/60,"") -> 1.5 | J12: Diligenciar : Nombre de la persona mas el proceso antes de IA
B13: Estructuración de campaña de comunicación interna SST | C13: Ocasional | D13: 720 | E13: Claude | F13: 180 | G13: =IFERROR(D13-F13,"") -> 540 | H13: =IFERROR(IF(D13>0,(D13-F13)/D13,0),"") -> 0.75 | I13: =IFERROR(G13/60,"") -> 9 | J13: Diligenciar : Nombre de la persona mas el proceso antes de IA
B14: Reestructuración campaña promoción de servicios Sácale Provecho a tu Caja | C14: Ocasional | D14: 1440 | E14: Claude | F14: 300 | G14: =IFERROR(D14-F14,"") -> 1140 | H14: =IFERROR(IF(D14>0,(D14-F14)/D14,0),"") -> 0.79166667 | I14: =IFERROR(G14/60,"") -> 19
B15: Auditoría del uso del logo COMFACESAR en piezas de terceros | C15: Ocasional | D15: 60 | E15: Claude | F15: 10 | G15: =IFERROR(D15-F15,"") -> 50 | H15: =IFERROR(IF(D15>0,(D15-F15)/D15,0),"") -> 0.83333333 | I15: =IFERROR(G15/60,"") -> 0.83333333 | J15: Cesar Reyes. Antes de IA: lectura del correo, descarga de la pieza, consulta manual del Manual de Marca y comparación visual del logo, redacción de la respuest
B16: Seguimiento solicitudes de diseño | C16: Diaria | D16: 15 | E16: Claude | F16: 1 | G16: =IFERROR(D16-F16,"") -> 14 | H16: =IFERROR(IF(D16>0,(D16-F16)/D16,0),"") -> 0.93333333 | I16: =IFERROR(G16/60,"") -> 0.23333333 | J16: Cesar Reyes. Antes de IA: revisión del correo, verificación de cada solicitud contra el Excel, aviso a los solicitantes y actualización del estado.
B17: Creación de piezas gráficas | C17: Diaria | D17: 120 | E17: Claude | F17: 90 | G17: =IFERROR(D17-F17,"") -> 30 | H17: =IFERROR(IF(D17>0,(D17-F17)/D17,0),"") -> 0.25 | I17: =IFERROR(G17/60,"") -> 0.5 | J17: Cesar Reyes. Antes de IA: lectura del brief, consulta del manual y la paleta del área, diagramación y proceso creativo.
B18: Informe mensual de producción gráfica | C18: Mensual | D18: 180 | E18: Claude | F18: 30 | G18: =IFERROR(D18-F18,"") -> 150 | H18: =IFERROR(IF(D18>0,(D18-F18)/D18,0),"") -> 0.83333333 | I18: =IFERROR(G18/60,"") -> 2.5 | J18: Cesar Reyes. Antes de IA:filtro manual por responsable y estado enviado, agrupación por mes según fecha de ingreso, suma de diseños por solicitante, comparación con el mes anterior y el mismo mes del año anterior.
B24: RESUMEN DE PRODUCTIVIDAD — RESULTADO DEL ASSESSMENT
B25: =COUNTA(B10:B22) | D25: =IFERROR(SUM(D10:D22)/60,0) | F25: =IFERROR(SUM(F10:F22)/60,0) | H25: =IFERROR((SUM(D10:D22)-SUM(F10:F22))/60,0)
B26: TAREAS MAPEADAS | D26: HRS/SEM ACTUAL | F26: HRS/SEM CON IA | H26: AHORRO HRS/SEM
B27: ⭕ Los datos de esta hoja se reflejan automáticamente en el RESUMEN GLOBAL. Comparte esa hoja con María Elvira.

Sheet SUB OPERATIVA
B1: IAM Intelligence™ · Assessment · SUB OPERATIVA
B3: Área: | C3: SUB OPERATIVA | E3: Fecha sesión: | H3: Sesión #:
B4: PARTICIPANTES
B5: ✓ Gennifer Alejandra Mira Salazar | D5: ✓ Jonnathan Johan Armenta
B8: DIAGNÓSTICO — TAREAS ACTUALES
B9: TAREA / REPORTE | C9: FRECUENCIA | D9: TIEMPO ACTUAL (minutos) | E9: HERRAMIENTA IA | F9: TIEMPO CON IA (minutos) | G9: AHORRO (min) | H9: % REDUCCIÓN | I9: AHORRO (HORAS) | J9: OBSERVACIONES
B10: Revisión de Costeos | C10: Diaria | D10: 10 | E10: Claude | F10: 2 | G10: =IFERROR(D10-F10,"") -> 8 | H10: =IFERROR(IF(D10>0,(D10-F10)/D10,0),"") -> 0.8 | I10: =IFERROR(G10/60,"") -> 0.13333333 | J10: Jonnathan: antes consumia tiempo realizando una tarea dinamica ahora al automatizarla en un asistente los correos que estan OK ni siquiera tengo que verlos ya solo me concentro en aquellos que tienen alguna alerta
B11: Informes Empresariales | C11: Ocasional | D11: 240 | E11: Claude | F11: 30 | G11: =IFERROR(D11-F11,"") -> 210 | H11: =IFERROR(IF(D11>0,(D11-F11)/D11,0),"") -> 0.875 | I11: =IFERROR(G11/60,"") -> 3.5 | J11: Gennifer: Ante solicitud de empresas sobre los usos de servicios y beneficios a sus empleados, realizaba tablas dinámicas manuales, ahora Claude analiza la información, crea tablas dinámicas y proyecta respuesta a la empresa.
B12: Seguimiendo Indicadores | C12: Mensual | D12: 480 | E12: Claude | F12: 40 | G12: =IFERROR(D12-F12,"") -> 440 | H12: =IFERROR(IF(D12>0,(D12-F12)/D12,0),"") -> 0.91666667 | I12: =IFERROR(G12/60,"") -> 7.3333333 | J12: Gennifer : Para realizar seguimiento a los indicadores, se organizaba de manera manual la información de presupuesto y ejecución por cada servicio y sede, al ser tan manual tardaba mucho, y posteriormente se organizaba presentación para grupo primario, ahora este trabajo se hace rápido y acorde a lo requerido, desde el archivo en Excel hasta la presentación en power point.
B13: Documento Especifico POA | C13: Ocasional | D13: 960 | E13: Claude | F13: 10 | G13: =IFERROR(D13-F13,"") -> 950 | H13: =IFERROR(IF(D13>0,(D13-F13)/D13,0),"") -> 0.98958333 | I13: =IFERROR(G13/60,"") -> 15.833333 | J13: Gennifer: Para crear un documento especifico, con lineamientos establecidos en otros documentos y parametros de calidad, la redacción del documento tardaria mucho tiempo. sin embargo con la herramienta se hizo de manera eficiente y acorde a lo requerido.
G14: =IFERROR(D14-F14,"") -> 0 | H14: =IFERROR(IF(D14>0,(D14-F14)/D14,0),"") -> 0 | I14: =IFERROR(G14/60,"") -> 0
G15: =IFERROR(D15-F15,"") -> 0 | H15: =IFERROR(IF(D15>0,(D15-F15)/D15,0),"") -> 0 | I15: =IFERROR(G15/60,"") -> 0
G16: =IFERROR(D16-F16,"") -> 0 | H16: =IFERROR(IF(D16>0,(D16-F16)/D16,0),"") -> 0 | I16: =IFERROR(G16/60,"") -> 0
G17: =IFERROR(D17-F17,"") -> 0 | H17: =IFERROR(IF(D17>0,(D17-F17)/D17,0),"") -> 0 | I17: =IFERROR(G17/60,"") -> 0
B19: RESUMEN DE PRODUCTIVIDAD — RESULTADO DEL ASSESSMENT
B20: =COUNTA(B10:B17) -> 4 | D20: =IFERROR(SUM(D10:D17)/60,0) -> 28.166667 | F20: =IFERROR(SUM(F10:F17)/60,0) -> 1.3666667 | H20: =IFERROR((SUM(D10:D17)-SUM(F10:F17))/60,0) -> 26.8
B21: TAREAS MAPEADAS | D21: HRS/SEM ACTUAL | F21: HRS/SEM CON IA | H21: AHORRO HRS/SEM
B22: ⭕ Los datos de esta hoja se reflejan automáticamente en el RESUMEN GLOBAL. Comparte esa hoja con María Elvira.

Sheet CONTABILIDAD
B1: IAM Intelligence™ · Assessment · CONTABILIDAD
B3: Área: | C3: CONTABILIDAD | E3: Fecha sesión: | H3: Sesión #:
B4: PARTICIPANTES
B5: ✓ Carlos | D5: ✓ Lisbeth Cuadrado Herrera
B8: DIAGNÓSTICO — TAREAS ACTUALES
B9: TAREA / REPORTE | C9: FRECUENCIA | D9: TIEMPO ACTUAL (minutos) | E9: HERRAMIENTA IA | F9: TIEMPO CON IA (minutos) | G9: AHORRO (min) | H9: % REDUCCIÓN | I9: AHORRO (HORAS) | J9: OBSERVACIONES
B10: Conciliaciones bancarias | C10: Mensual | D10: 480 | E10: Claude | F10: 180 | G10: =IFERROR(D10-F10,"") -> 300 | H10: =IFERROR(IF(D10>0,(D10-F10)/D10,0),"") -> 0.625 | I10: =IFERROR(G10/60,"") -> 5 | J10: Carlos: Las conciliaciones bancarias tomaban un tiempo de 2 días aproximadamente. Actualmente con las herramientas aprendidas en se toman 1 día completarlas. La disminución de la operatividad ha sido alta lo que peremite enfocarse en otras partes del procesos, por ejemplo analizar las razones por las cuáles quedaorn partidas pendientes en libro o extracto.
B11: Reporte de viáticos | C11: Mensual | D11: 240 | E11: Claude | F11: 10 | G11: =IFERROR(D11-F11,"") -> 230 | H11: =IFERROR(IF(D11>0,(D11-F11)/D11,0),"") -> 0.95833333 | I11: =IFERROR(G11/60,"") -> 3.8333333 | J11: El reporte que se envia al área de G.H tomaba aproximadamente 4 horas debido a la depuación de las pártidas que habia por realizar las cuáles facilmente podían ser más de 100. Actualmente claude analiza la información y deja las partidas que efectivamente estan pendientes. Además que en esos mismo 10 minutos claude genera KPI de alertas y un tablero dinámico en formato HTML.
B12: Calendario de obligaciones tributarias | C12: Ocasional | D12: 60 | E12: Claude | F12: 5 | G12: =IFERROR(D12-F12,"") -> 55 | H12: =IFERROR(IF(D12>0,(D12-F12)/D12,0),"") -> 0.91666667 | I12: =IFERROR(G12/60,"") -> 0.91666667 | J12: Carlos: El calendario de las obligaciones tributarias es un formato que se diseña a principio de año y puede tomar entre 40-60 minutos hacerlo. Actualmente con claude el tiempo de diseño fueron 5 minutos. Además que se estructuró un proceso formal para que llegaran nofitifaciones a los responsables de cada obligación tributaria y evitar posibles sanciones por presentación extemporanea de las obligaciones
B13: Reporte de retención en la fuente | C13: Mensual | D13: 120 | E13: Claude | F13: 30 | G13: =IFERROR(D13-F13,"") -> 90 | H13: =IFERROR(IF(D13>0,(D13-F13)/D13,0),"") -> 0.75 | I13: =IFERROR(G13/60,"") -> 1.5 | J13: Carlos: Estructurar y organizar la información para presentar la retención en la fuente tomaba aproximidamente 2horas. Con el agente de IA el tiempo se redujo a 30minutos que es básicamente para revisar debido a que el agente realiza toda la parte operativa.
G14: =IFERROR(D14-F14,"") -> 0 | H14: =IFERROR(IF(D14>0,(D14-F14)/D14,0),"") -> 0 | I14: =IFERROR(G14/60,"") -> 0
G15: =IFERROR(D15-F15,"") -> 0 | H15: =IFERROR(IF(D15>0,(D15-F15)/D15,0),"") -> 0 | I15: =IFERROR(G15/60,"") -> 0
G16: =IFERROR(D16-F16,"") -> 0 | H16: =IFERROR(IF(D16>0,(D16-F16)/D16,0),"") -> 0 | I16: =IFERROR(G16/60,"") -> 0
G17: =IFERROR(D17-F17,"") -> 0 | H17: =IFERROR(IF(D17>0,(D17-F17)/D17,0),"") -> 0 | I17: =IFERROR(G17/60,"") -> 0
B19: RESUMEN DE PRODUCTIVIDAD — RESULTADO DEL ASSESSMENT
B20: =COUNTA(B10:B17) -> 4 | D20: =IFERROR(SUM(D10:D17)/60,0) -> 15 | F20: =IFERROR(SUM(F10:F17)/60,0) -> 3.75 | H20: =IFERROR((SUM(D10:D17)-SUM(F10:F17))/60,0) -> 11.25
B21: TAREAS MAPEADAS | D21: HRS/SEM ACTUAL | F21: HRS/SEM CON IA | H21: AHORRO HRS/SEM
B22: ⭕ Los datos de esta hoja se reflejan automáticamente en el RESUMEN GLOBAL. Comparte esa hoja con María Elvira.

Sheet IPS
A1: k | B1: IAM Intelligence™ · Assessment · IPS
B3: Área: | C3: IPS | E3: Fecha sesión: | H3: Sesión #:
B4: PARTICIPANTES
B5: ✓ Daniel Danilo Pozo Murgas
B8: DIAGNÓSTICO — TAREAS ACTUALES
B9: TAREA / REPORTE | C9: FRECUENCIA | D9: TIEMPO ACTUAL (minutos) | E9: HERRAMIENTA IA | F9: TIEMPO CON IA (minutos) | G9: AHORRO (min) | H9: % REDUCCIÓN | I9: AHORRO (HORAS) | J9: OBSERVACIONES
B10: Alimentación del Sistema de gestión de SST con Comfacesar IPS, conceptos de aptitud para seguimientos y demas actividades del sistema | C10: Mensual | D10: 6400 | E10: Claude | F10: 480 | G10: =IFERROR(D10-F10,"") -> 5920 | H10: =IFERROR(IF(D10>0,(D10-F10)/D10,0),"") -> 0.925 | I10: =IFERROR(G10/60,"") -> 98.666667 | J10: Danilo Pozo, Antes de forma manual se realizaban las cartas de recomendaciones por trabajdor (En los meses de enero tenemos 150 ingresos), por el volumen de la información se generaban algunas inconsistencias en los informes, de igual formas debiamos llenar de manera manual las matrices de ingresos y SVE (Actualmente tenemos 5). A traves de esta Herramienta podemos perfeccionar el ejercicio y realizarlo en un dia.
B11: Conceptos de aptitud del examen médico ocupacional: recomendaciones, alertas y sistema de vigilancia | C11: Por confirmar | E11: Claude | G11: =IFERROR(D11-F11,"") | H11: =IFERROR(IF(D11>0,(D11-F11)/D11,0),"") | I11: =IFERROR(G11/60,"") | J11: Lo registró Lucía el 9 de octubre de 2026 a partir del acta de la Sesión 2 del 9 de septiembre de 2026. El área trajo la medición hecha por ellos mismos: lo que les tomaba dos meses salió en cinco minutos. Antes se revisaba caso por caso para identificar qué personal viene con recomendaciones, cuál genera alerta y a qué sistema de vigilancia pertenece. El acta pide expresamente registrarlo en el tablero del programa. Los minutos quedan en blanco porque el acta dice dos meses y no dice si son dos meses de calendario o de trabajo efectivo, y esa diferencia cambia la cifra por completo. Lo tiene que decir el área.
G12: =IFERROR(D12-F12,"") -> 0 | H12: =IFERROR(IF(D12>0,(D12-F12)/D12,0),"") -> 0
G13: =IFERROR(D13-F13,"") -> 0 | H13: =IFERROR(IF(D13>0,(D13-F13)/D13,0),"") -> 0
G14: =IFERROR(D14-F14,"") -> 0 | H14: =IFERROR(IF(D14>0,(D14-F14)/D14,0),"") -> 0
G15: =IFERROR(D15-F15,"") -> 0 | H15: =IFERROR(IF(D15>0,(D15-F15)/D15,0),"") -> 0
G16: =IFERROR(D16-F16,"") -> 0 | H16: =IFERROR(IF(D16>0,(D16-F16)/D16,0),"") -> 0
G17: =IFERROR(D17-F17,"") -> 0 | H17: =IFERROR(IF(D17>0,(D17-F17)/D17,0),"") -> 0
B19: RESUMEN DE PRODUCTIVIDAD — RESULTADO DEL ASSESSMENT
B20: =COUNTA(B10:B17) -> 1 | D20: =IFERROR(SUM(D10:D17)/60,0) -> 106.66667 | F20: =IFERROR(SUM(F10:F17)/60,0) -> 8 | H20: =IFERROR((SUM(D10:D17)-SUM(F10:F17))/60,0) -> 98.666667
B21: TAREAS MAPEADAS | D21: HRS/SEM ACTUAL | F21: HRS/SEM CON IA | H21: AHORRO HRS/SEM
B22: ⭕ Los datos de esta hoja se reflejan automáticamente en el RESUMEN GLOBAL. Comparte esa hoja con María Elvira.

Sheet AGENCIA DE EMPLEO
B1: IAM Intelligence™ · Assessment · AGENCIA DE EMPLEO
B3: Área: | C3: AGENCIA DE EMPLEO | E3: Fecha sesión: | F3: 13 de agosto | H3: Sesión #: | I3: 1
B4: PARTICIPANTES
B5: ✓ Lina Rincón | D5: ✓ José Jaime Maya López
B8: DIAGNÓSTICO — TAREAS ACTUALES
B9: TAREA / REPORTE | C9: FRECUENCIA | D9: TIEMPO ACTUAL (minutos) | E9: HERRAMIENTA IA | F9: TIEMPO CON IA (minutos) | G9: AHORRO (min) | H9: % REDUCCIÓN | I9: AHORRO (HORAS) | J9: OBSERVACIONES
B10: Proceso de intermediación laboral validación de hojas de vida | C10: Diaria | D10: 32 | E10: Claude | F10: 22 | G10: =IFERROR(D10-F10,"") -> 10 | H10: =IFERROR(IF(D10>0,(D10-F10)/D10,0),"") -> 0.3125 | I10: =IFERROR(G10/60,"") -> 0.16666667 | J10: Intermediador Laboral: Anteriormente, la validación de los candidatos postulados a una vacante se realizaba mediante la revisión individual de cada hoja de vida, con el fin de identificar cuáles cumplían con el perfil requerido por el empresario. Posteriormente, las hojas de vida seleccionadas eran remitidas por correo electrónico, sin contar con una ficha de evaluación que permitiera evidenciar la puntuación o valoración asignada a cada candidato.
B11: Proceso de recobros, creación agente Matías | C11: Mensual | D11: 1200 | E11: Claude | F11: 600 | G11: =IFERROR(D11-F11,"") -> 600 | H11: =IFERROR(IF(D11>0,(D11-F11)/D11,0),"") -> 0.5 | I11: =IFERROR(IF(E11>0,(E11-G11)/E11,0),"") | J11: Eliana: Anteriormente, el proceso de recobro se realizaba de forma manual por el Auxiliar FOSFEC: descargaba el reporte de Zenith, depuraba los periodos en Excel, buscaba el correo de cada beneficiario en la consulta de solicitudes y elaboraba y enviaba una a una las cartas de restitución. El seguimiento quincenal, el control de pagos y acuerdos de pago y el listado para cartera y cobranzas se llevaban manualmente, sin un tablero consolidado de la gestión.
B12: Laboratorio de Empleo, ampliación de los resultados a empresarios | C12: Diaria | D12: 25 | E12: Claude | F12: 15 | G12: =IFERROR(D12-F12,"") -> 10 | H12: =IFERROR(IF(D12>0,(D12-F12)/D12,0),"") -> 0.4 | J12: Alejandra: En el proceso de Laboratorio de Empleo, los informes de resultados de las pruebas psicotécnicas entregados a los empresarios contenían únicamente los puntajes obtenidos por los candidatos, sin incluir un análisis que permitiera identificar si sus competencias y habilidades se ajustaban al perfil del cargo solicitado. Esto limitaba la utilidad del informe como herramienta de apoyo para la toma de decisiones en los procesos de selección de personal.
B13: Creación de informe con los indicadores de la Agencia de Empleo | C13: Ocasional | D13: 300 | E13: Claude | F13: 30 | G13: =IFERROR(D13-F13,"") -> 270 | H13: =IFERROR(IF(D13>0,(D13-F13)/D13,0),"") -> 0.9
B14: Tablero de indicadores de Agencia de Empleo para Grupo Primario | C14: Mensual | D14: 180 | E14: Claude | F14: 60 | G14: =IFERROR(D14-F14,"") -> 120 | H14: =IFERROR(IF(D14>0,(D14-F14)/D14,0),"") -> 0.66666667
B15: Validación de requisitos programa Impulso Empresarial | G15: =IFERROR(D15-F15,"") -> 0 | H15: =IFERROR(IF(D15>0,(D15-F15)/D15,0),"") -> 0
G16: =IFERROR(D16-F16,"") -> 0 | H16: =IFERROR(IF(D16>0,(D16-F16)/D16,0),"") -> 0
G17: =IFERROR(D17-F17,"") -> 0 | H17: =IFERROR(IF(D17>0,(D17-F17)/D17,0),"") -> 0
B19: RESUMEN DE PRODUCTIVIDAD — RESULTADO DEL ASSESSMENT
B20: =COUNTA(B10:B17) -> 6 | D20: =IFERROR(SUM(D10:D17)/60,0) -> 28.95 | F20: =IFERROR(SUM(F10:F17)/60,0) -> 12.116667 | H20: =IFERROR((SUM(D10:D17)-SUM(F10:F17))/60,0) -> 16.833333
B21: TAREAS MAPEADAS | D21: HRS/SEM ACTUAL | F21: HRS/SEM CON IA | H21: AHORRO HRS/SEM
B22: ⭕ Los datos de esta hoja se reflejan automáticamente en el RESUMEN GLOBAL. Comparte esa hoja con María Elvira.

Sheet SUBSIDIO
B1: IAM Intelligence™ · Assessment · SUBSIDIO
B3: Área: | C3: SUBSIDIO | E3: Fecha sesión: | H3: Sesión #:
B4: PARTICIPANTES
B7: ✓ José Luciano Contreras Jaime | D7: ✓ Carlos Andrés García Martínez | F7: ✓ Avelino Romero | H7: ✓ Cindy Rodríguez
B8: DIAGNÓSTICO — TAREAS ACTUALES
B9: TAREA / REPORTE | C9: FRECUENCIA | D9: TIEMPO ACTUAL (minutos) | E9: HERRAMIENTA IA | F9: TIEMPO CON IA (minutos) | G9: AHORRO (min) | H9: % REDUCCIÓN | I9: AHORRO (HORAS) | J9: OBSERVACIONES
B10: PRESENTACION CONSEJO | C10: Mensual | D10: 2880 | E10: Claude | F10: 30 | G10: =IFERROR(D10-F10,"") -> 2850 | H10: =IFERROR(IF(D10>0,(D10-F10)/D10,0),"") -> 0.98958333 | J10: Anteriormente, la elaboración de las gráficas para el Consejo Directivo se realizaba de manera manual, requiriendo tiempo para organizar, consolidar y presentar la información. Actualmente, utilizo inteligencia artificial que automatiza este proceso, generando las gráficas de manera más ágil y facilitando el análisis y la presentación de los resultados.
B11: GESTION CORREO | C11: Diaria | D11: 60 | E11: Claude | F11: 15 | G11: =IFERROR(D11-F11,"") -> 45 | H11: =IFERROR(IF(D11>0,(D11-F11)/D11,0),"") -> 0.75 | J11: Anteriormente, la gestión del correo electrónico requería revisar, clasificar y dar seguimiento manualmente a los mensajes. Actualmente, cuento con un agente de inteligencia artificial que me apoya en la gestión del correo, facilitando la organización, priorización y seguimiento de las comunicaciones, lo que permite optimizar el tiempo y concentrarme en actividades de mayor valor.
B12: TABLERO DE AFILIACIONES | C12: Diaria | D12: 120 | E12: Claude | F12: 20 | G12: =IFERROR(D12-F12,"") -> 100 | H12: =IFERROR(IF(D12>0,(D12-F12)/D12,0),"") -> 0.83333333 | J12: Anteriormente, la verificación de las solicitudes de afiliación se realizaba de manera manual, revisando uno a uno los requisitos y criterios establecidos. Actualmente, se utilizan tableros apoyados en inteligencia artificial que analizan la información y determinan si cada solicitud procede o no procede, facilitando la toma de decisiones, reduciendo tiempos de revisión y mejorando la trazabilidad del proceso.
B13: GESTION CORREO | C13: Diaria | D13: 1440 | E13: Claude | F13: 180 | G13: =IFERROR(D13-F13,"") -> 1260 | H13: =IFERROR(IF(D13>0,(D13-F13)/D13,0),"") -> 0.875 | J13: Se implemento un agente de inteligencia artificial que apoya la gestión diaria del correo electrónico, identificando mensajes relevantes, organizando la información y haciendo reparto de los correos a los funcioanrios encargados y seguimiento de las solicitudes. Esto permite agilizar la gestión de las respuestas a los usuarios y optimizar el tiempo destinado a estas actividades.
B14: Cruce con la Registraduría: filtrado por causal y anotaciones | C14: Por confirmar | D14: 120 | E14: Claude | F14: 10 | G14: =IFERROR(D14-F14,"") | H14: =IFERROR(IF(D14>0,(D14-F14)/D14,0),"") | I14: =IFERROR(G14/60,"") | J14: Lo registró Lucía el 9 de octubre de 2026 a partir del acta de la Sesión 3 del 8 de septiembre de 2026. Medición tomada en sesión: el archivo que devuelve la Registraduría se pasaba a Excel y se filtraba causal por causal a mano, con las anotaciones, y tomaba dos horas cada vez. Con el proceso montado queda en unos diez minutos y el resultado ya sale con la información necesaria para notificar. La frecuencia la tiene que poner el área: el acta dice cada vez que llega el archivo y no dice cada cuánto llega.
G15: =IFERROR(D15-F15,"") -> 0 | H15: =IFERROR(IF(D15>0,(D15-F15)/D15,0),"") -> 0
G16: =IFERROR(D16-F16,"") -> 0 | H16: =IFERROR(IF(D16>0,(D16-F16)/D16,0),"") -> 0
G17: =IFERROR(D17-F17,"") -> 0 | H17: =IFERROR(IF(D17>0,(D17-F17)/D17,0),"") -> 0
B19: RESUMEN DE PRODUCTIVIDAD — RESULTADO DEL ASSESSMENT
B20: =COUNTA(B10:B17) -> 4 | D20: =IFERROR(SUM(D10:D17)/60,0) -> 75 | F20: =IFERROR(SUM(F10:F17)/60,0) -> 4.0833333 | H20: =IFERROR((SUM(D10:D17)-SUM(F10:F17))/60,0) -> 70.916667
B21: TAREAS MAPEADAS | D21: HRS/SEM ACTUAL | F21: HRS/SEM CON IA | H21: AHORRO HRS/SEM
B22: ⭕ Los datos de esta hoja se reflejan automáticamente en el RESUMEN GLOBAL. Comparte esa hoja con María Elvira.

Sheet TALENTO HUMANO
B1: IAM Intelligence™ · Assessment · TALENTO HUMANO
B3: Área: | C3: TALENTO HUMANO | E3: Fecha sesión: | H3: Sesión #:
B4: PARTICIPANTES
B5: ✓ María Loretta Fuentes Carrillo | D5: ✓ Roí David Carrillo Soto
B8: DIAGNÓSTICO — TAREAS ACTUALES
B9: TAREA / REPORTE | C9: FRECUENCIA | D9: TIEMPO ACTUAL (minutos) | E9: HERRAMIENTA IA | F9: TIEMPO CON IA (minutos) | G9: AHORRO (min) | H9: % REDUCCIÓN | I9: AHORRO (HORAS) | J9: OBSERVACIONES
B10: GENERACION AUTOMATICAS DE ACTAS DE CONTRATOS | C10: Ocasional | D10: 20 | E10: Claude | F10: 3 | G10: =IFERROR(D10-F10,"") -> 17 | H10: =IFERROR(IF(D10>0,(D10-F10)/D10,0),"") -> 0.85 | I10: =IFERROR(G10/60,"") -> 0.28333333 | J10: Maria Loretta: Se automatizó la generación de actas de inicio de COMFACESAR a partir de los expedientes contractuales escaneados (contrato, solicitud, propuesta y póliza), extrayendo y verificando datos clave —objeto, valor, plazo, garantías y fecha de aprobación jurídica de la póliza— para producir el documento oficial (formato F-J-001 v9) editable y listo para firma
G11: =IFERROR(D11-F11,"") -> 0 | H11: =IFERROR(IF(D11>0,(D11-F11)/D11,0),"") -> 0
G12: =IFERROR(D12-F12,"") -> 0 | H12: =IFERROR(IF(D12>0,(D12-F12)/D12,0),"") -> 0
G13: =IFERROR(D13-F13,"") -> 0 | H13: =IFERROR(IF(D13>0,(D13-F13)/D13,0),"") -> 0
G14: =IFERROR(D14-F14,"") -> 0 | H14: =IFERROR(IF(D14>0,(D14-F14)/D14,0),"") -> 0
G15: =IFERROR(D15-F15,"") -> 0 | H15: =IFERROR(IF(D15>0,(D15-F15)/D15,0),"") -> 0
G16: =IFERROR(D16-F16,"") -> 0 | H16: =IFERROR(IF(D16>0,(D16-F16)/D16,0),"") -> 0
G17: =IFERROR(D17-F17,"") -> 0 | H17: =IFERROR(IF(D17>0,(D17-F17)/D17,0),"") -> 0
B19: RESUMEN DE PRODUCTIVIDAD — RESULTADO DEL ASSESSMENT
B20: =COUNTA(B10:B17) -> 1 | D20: =IFERROR(SUM(D10:D17)/60,0) -> 0.33333333 | F20: =IFERROR(SUM(F10:F17)/60,0) -> 0.05 | H20: =IFERROR((SUM(D10:D17)-SUM(F10:F17))/60,0) -> 0.28333333
B21: TAREAS MAPEADAS | D21: HRS/SEM ACTUAL | F21: HRS/SEM CON IA | H21: AHORRO HRS/SEM
B22: ⭕ Los datos de esta hoja se reflejan automáticamente en el RESUMEN GLOBAL. Comparte esa hoja con María Elvira.

Sheet CUMPLIMIENTO
B1: IAM Intelligence™ · Assessment · CUMPLIMIENTO
B3: Área: | C3: CUMPLIMIENTO | E3: Fecha sesión: | H3: Sesión #:
B4: PARTICIPANTES
B5: ✓ Lilibeth Del Carmen Costa Méndez | D5: ✓ Mario Pérez | F5: ✓ Juan Carlos Guillen Escobar
B8: DIAGNÓSTICO — TAREAS ACTUALES
B9: TAREA / REPORTE | C9: FRECUENCIA | D9: TIEMPO ACTUAL (minutos) | E9: HERRAMIENTA IA | F9: TIEMPO CON IA (minutos) | G9: AHORRO (min) | H9: % REDUCCIÓN | I9: AHORRO (HORAS) | J9: OBSERVACIONES
B10: Seguimiento de los POAs en la perspectiva de eficiencia | C10: Mensual | D10: 32 | G10: =IFERROR(D10-F10,"") -> 32 | H10: =IFERROR(IF(D10>0,(D10-F10)/D10,0),"") -> 1 | I10: =IFERROR(G10/60,"") -> 0.53333333
G11: =IFERROR(D11-F11,"") -> 0 | H11: =IFERROR(IF(D11>0,(D11-F11)/D11,0),"") -> 0
G12: =IFERROR(D12-F12,"") -> 0 | H12: =IFERROR(IF(D12>0,(D12-F12)/D12,0),"") -> 0
G13: =IFERROR(D13-F13,"") -> 0 | H13: =IFERROR(IF(D13>0,(D13-F13)/D13,0),"") -> 0
G14: =IFERROR(D14-F14,"") -> 0 | H14: =IFERROR(IF(D14>0,(D14-F14)/D14,0),"") -> 0
G15: =IFERROR(D15-F15,"") -> 0 | H15: =IFERROR(IF(D15>0,(D15-F15)/D15,0),"") -> 0
G16: =IFERROR(D16-F16,"") -> 0 | H16: =IFERROR(IF(D16>0,(D16-F16)/D16,0),"") -> 0
